Workbook

Sheet Dashboard
A1: 📊 PAINEL DE ESTUDOS — PMMA 2026
A3: Soldado do Quadro de Praças (QP) · Prova em 11/10/2026 · Atualize Cronograma, TAF e Simulado para alimentar este painel
B5: % DO EDITAL ESTUDADO | D5: QUESTÕES RESOLVIDAS | F5: TAXA DE ACERTO GERAL | H5: DIAS ATÉ A PROVA | J5: TREINOS DE TAF REGISTRADOS
B6: =IFERROR(COUNTIF(Controle_Edital!E2:E93,"Sim")/COUNTA(Controle_Edital!A2:A93),0) | D6: =SUM(Cronograma!L2:L156) | F6: =IFERROR(SUM(Cronograma!M2:M156)/SUM(Cronograma!L2:L156),0) | H6: =DATE(2026,10,11)-TODAY() | J6: =COUNTA(TAF_Semanal!A2:A19)
A9: 📘 Progresso do Edital por Matéria | G9: 🎯 Taxa de Acerto por Matéria
A26: 🥧 Estudado x Pendente (Edital) | G26: 📈 Notas dos Simulados

Sheet Cronograma
A1: Data | B1: Dia | C1: Semana | D1: Matéria | E1: Tema | F1: Tipo | G1: Status Probabilidade | H1: 🔥 Quente | I1: Estudei? | J1: Tempo (min) | K1: Fiz Questões? | L1: Qtd Questões | M1: Acertos | N1: Taxa de Acerto
A2: 46223 | B2: Segunda | C2: Semana 1 | D2: Língua Portuguesa | E2: Interpretação e compreensão textual | F2: Teoria + Questões | G2: Alta | H2: 🔥 | I2: Sim | J2: 20 | K2: Sim | L2: 4 | M2: 4 | N2: 1
A3: 46223 | B3: Segunda | C3: Semana 1 | D3: Língua Portuguesa | E3: Reescrita de frases e parágrafos | F3: Teoria + Questões | G3: Alta | H3: 🔥 | I3: Sim | J3: 20 | K3: Sim | L3: 4 | M3: 3 | N3: 0.75
A4: 46224 | B4: Terça | C4: Semana 1 | D4: Legislação Institucional | E4: Estatuto 6.513/95: Hierarquia, disciplina, postos e graduações | F4: Teoria + Questões | G4: Alta | H4: 🔥 | I4: Sim | J4: 20 | K4: Sim | L4: 3 | M4: 3 | N4: 1
A5: 46224 | B5: Terça | C5: Semana 1 | D5: Legislação Institucional | E5: Estatuto 6.513/95: Direitos, deveres e ética policial-militar | F5: Teoria + Questões | G5: Alta | H5: 🔥 | I5: Sim | J5: 20 | K5: Sim | L5: 4 | M5: 4 | N5: 1
A6: 46224 | B6: Terça | C6: Semana 1 | D6: Legislação Institucional | E6: Estatuto 6.513/95: Ingresso, carreira e situações do PM | F6: Teoria + Questões | G6: Alta | H6: 🔥 | I6: Sim | J6: 20 | K6: Sim | L6: 4 | M6: 4 | N6: 1
A7: 46225 | B7: Quarta | C7: Semana 1 | D7: História do Brasil | E7: Contribuição de índios e negros na formação do Brasil | F7: Teoria + Questões | G7: Média | H7: - | I7: Sim | J7: 20 | K7: Sim | L7: 2 | M7: 2 | N7: 1
A8: 46225 | B8: Quarta | C8: Semana 1 | D8: História do Brasil | E8: Formação do Brasil Contemporâneo | F8: Teoria + Questões | G8: Média | H8: - | I8: Sim | J8: 20 | K8: Sim | L8: 2 | M8: 2 | N8: 1
A9: 46225 | B9: Quarta | C9: Semana 1 | D9: História do Maranhão | E9: França Equinocial: expedição de La Touche | F9: Teoria + Questões | G9: Alta | H9: 🔥 | I9: Sim | J9: 20 | K9: Sim | L9: 3 | M9: 3 | N9: 1
A10: 46226 | B10: Quinta | C10: Semana 1 | D10: Geografia do Brasil | E10: Integração à internacionalização da economia | F10: Teoria + Questões | G10: Média | H10: - | I10: Sim | J10: 20 | K10: Sim | L10: 3 | M10: 3 | N10: 1
A11: 46226 | B11: Quinta | C11: Semana 1 | D11: Geografia do Brasil | E11: Industrialização e organização do espaço | F11: Teoria + Questões | G11: Alta | H11: 🔥 | I11: Sim | J11: 20 | K11: Sim | L11: 2 | M11: 2 | N11: 1
A12: 46226 | B12: Quinta | C12: Semana 1 | D12: Geografia do Maranhão | E12: Localização: superfície, limites e APAs | F12: Teoria + Questões | G12: Média | H12: - | I12: Sim | J12: 20 | K12: Sim | L12: 4 | M12: 4 | N12: 1
A13: 46227 | B13: Sexta | C13: Semana 1 | D13: Noções de Informática | E13: Sistema operacional: Windows e Linux | F13: Teoria + Questões | G13: Alta | H13: 🔥 | I13: Sim | J13: 20 | K13: Sim | L13: 5 | M13: 4 | N13: 0.8
... A16: 46228 | B16: Sábado | C16: Semana 1 | D16: Simulado Geral | E16: Simulado completo (ver aba Simulado Semanal) | F16: Simulado | G16: - | H16: - | I16: Sim | J16: 60 | K16: Não | L16: 0 | M16: 0 | N16: 0
A17: 46229 | B17: Domingo | C17: Semana 1 | D17: TAF | E17: Teste/treino físico (ver aba TAF Semanal) | F17: TAF | G17: - | H17: - | I17: Não | J17: 0 | K17: Não | L17: 0 | M17: 0 | N17: =IFERROR(M17/L17,"")
A18: 46230 | B18: Segunda | C18: Semana 2 | D18: Língua Portuguesa | E18: Coesão textual (referenciação, conectores) | F18: Teoria + Questões | G18: Alta | H18: 🔥 | I18: Sim | J18: 0 | K18: Sim | L18: 4 | M18: 2 | N18: 0.5
A19: 46230 | B19: Segunda | C19: Semana 2 | D19: Língua Portuguesa | E19: Morfossintaxe: classes de palavras | F19: Teoria + Questões | G19: Alta | H19: 🔥 | I19: Sim | J19: 0 | K19: Sim | L19: 4 | M19: 3 | N19: 0.75
A20: 46231 | B20: Terça | C20: Semana 2 | D20: Legislação Institucional | E20: Estatuto 6.513/95: Promoções (Art. 78 e 79-A) | F20: Teoria + Questões | G20: Alta | H20: - | I20: Sim | J20: 0 | K20: Sim | L20: 6 | M20: 5 | N20: 0.83333333
A21: 46231 | B21: Terça | C21: Semana 2 | D21: Legislação Institucional | E21: Lei 14.751/23: Disposições gerais e competências das PMs | F21: Teoria + Questões | G21: Alta | H21: - | I21: Sim | J21: 0 | K21: Sim | L21: 5 | M21: 5 | N21: 1
A22: 46231 | B22: Terça | C22: Semana 2 | D22: Legislação Institucional | E22: Lei 14.751/23: Organização (direção/apoio/execução/correição) | F22: Teoria + Questões | G22: Alta | H22: - | I22: Sim | J22: 0 | K22: Sim | L22: 5 | M22: 3 | N22: 0.6
A23: 46232 | B23: Quarta | C23: Semana 2 | D23: História do Brasil | E23: República Velha e estruturas oligárquicas | F23: Teoria + Questões | G23: Alta | H23: 🔥 | I23: Sim | J23: 0 | K23: Sim | L23: 2 | M23: 2 | N23: 1
A24: 46232 | B24: Quarta | C24: Semana 2 | D24: História do Maranhão | E24: Fundação de São Luís | F24: Teoria + Questões | G24: Alta | H24: 🔥 | I24: Sim | J24: 0 | K24: Sim | L24: 1 | M24: 1 | N24: 1
A25: 46232 | B25: Quarta | C25: Semana 2 | D25: História do Maranhão | E25: Batalha de Guaxenduba | F25: Teoria + Questões | G25: Alta | H25: 🔥 | I25: Sim | J25: 0 | K25: Sim | L25: 1 | M25: 1 | N25: 1
A26: 46233 | B26: Quinta | C26: Semana 2 | D26: Geografia do Brasil | E26: Rede brasileira de transportes | F26: Teoria + Questões | G26: Média | H26: - | I26: Sim | J26: 0 | K26: Sim | L26: 2 | M26: 2 | N26: 1
A27: 46233 | B27: Quinta | C27: Semana 2 | D27: Geografia do Maranhão | E27: Parques nacionais | F27: Teoria + Questões | G27: Baixa | H27: - | I27: Sim | J27: 0 | K27: Sim | L27: 2 | M27: 2 | N27: 1
A28: 46233 | B28: Quinta | C28: Semana 2 | D28: Geografia do Maranhão | E28: Clima do Maranhão: pluviosidade e temperatura | F28: Teoria + Questões | G28: Alta | H28: 🔥 | I28: Sim | J28: 0 | K28: Sim | L28: 2 | M28: 2 | N28: 1
A29: 46234 | B29: Sexta | C29: Semana 2 | D29: Noções de Informática | E29: Redes de computadores: internet e intranet | F29: Teoria + Questões | G29: Alta | H29: 🔥 | I29: Sim | J29: 0 | K29: Sim | L29: 8 | M29: 7 | N29: 0.875
... A31: 46234 | B31: Sexta | C31: Semana 2 | D31: Raciocínio Lógico | E31: Lógica de argumentação: analogias, inferências, deduções | F31: Teoria + Questões | G31: Média | H31: - | I31: Sim | J31: 0 | K31: Sim | L31: 2 | M31: 1 | N31: 0.5
A32: 46235 | B32: Sábado | C32: Semana 2 | D32: Simulado Geral | E32: Simulado completo (ver aba Simulado Semanal) | F32: Simulado | G32: - | H32: - | I32: Não | J32: 0 | K32: Não | L32: 0 | M32: 0 | N32: =IFERROR(M32/L32,"")
A33: 46236 | B33: Domingo | C33: Semana 2 | D33: TAF | E33: Teste/treino físico (ver aba TAF Semanal) | F33: TAF | G33: - | H33: - | I33: Não | J33: 0 | K33: Não | L33: 0 | M33: 0 | N33: =IFERROR(M33/L33,"")
A34: 46237 | B34: Segunda | C34: Semana 3 | D34: Língua Portuguesa | E34: Concordância verbal e nominal | F34: Teoria + Questões | G34: Alta | H34: 🔥 | I34: Não | J34: 0 | K34: Não | L34: 0 | M34: 0 | N34: =IFERROR(M34/L34,"")
A35: 46237 | B35: Segunda | C35: Semana 3 | D35: Língua Portuguesa | E35: Regência verbal/nominal, crase e pontuação | F35: Teoria + Questões | G35: Alta | H35: 🔥 | I35: Não | J35: 0 | K35: Não | L35: 0 | M35: 0 | N35: =IFERROR(M35/L35,"")
A36: 46238 | B36: Terça | C36: Semana 3 | D36: Legislação Institucional | E36: Lei 14.751/23: Hierarquia, quadros e efetivos | F36: Teoria + Questões | G36: Alta | H36: - | I36: Não | J36: 0 | K36: Não | L36: 0 | M36: 0 | N36: =IFERROR(M36/L36,"")
A37: 46238 | B37: Terça | C37: Semana 3 | D37: Legislação Institucional | E37: Lei 14.751/23: Garantias dos militares | F37: Teoria + Questões | G37: Média | H37: - | I37: Não | J37: 0 | K37: Não | L37: 0 | M37: 0 | N37: =IFERROR(M37/L37,"")
A38: 46238 | B38: Terça | C38: Semana 3 | D38: Legislação Institucional | E38: Lei 12.896/26: Natureza jurídica e competências da PMMA (Art. 1-4) | F38: Teoria + Questões | G38: Alta | H38: 🔥 | I38: Não | J38: 0 | K38: Não | L38: 0 | M38: 0 | N38: =IFERROR(M38/L38,"")
A39: 46239 | B39: Quarta | C39: Semana 3 | D39: História do Brasil | E39: Economia e sociedade: o café | F39: Teoria + Questões | G39: Média | H39: - | I39: Não | J39: 0 | K39: Não | L39: 0 | M39: 0 | N39: =IFERROR(M39/L39,"")
A40: 46239 | B40: Quarta | C40: Semana 3 | D40: História do Brasil | E40: Revolução de 1930 | F40: Teoria + Questões | G40: Alta | H40: 🔥 | I40: Sim | J40: 0 | K40: Não | L40: 0 | M40: 0 | N40: 0
A41: 46239 | B41: Quarta | C41: Semana 3 | D41: História do Maranhão | E41: Capitães-mores do Maranhão | F41: Teoria + Questões | G41: Baixa | H41: - | I41: Sim | J41: 0 | K41: Não | L41: 0 | M41: 0 | N41: 0
A42: 46240 | B42: Quinta | C42: Semana 3 | D42: Geografia do Brasil | E42: Estrutura urbana e grandes metrópoles | F42: Teoria + Questões | G42: Alta | H42: 🔥 | I42: Não | J42: 0 | K42: Não | L42: 0 | M42: 0 | N42: =IFERROR(M42/L42,"")
A43: 46240 | B43: Quinta | C43: Semana 3 | D43: Geografia do Brasil | E43: Fronteiras agrícolas: Centro-Oeste e Amazônia | F43: Teoria + Questões | G43: Alta | H43: 🔥 | I43: Sim | J43: 0 | K43: Não | L43: 0 | M43: 0 | N43: 0
...

Sheet Controle_Edital
A1: Matéria | B1: Tópico | C1: Status Probabilidade | D1: 🔥 Tema Quente | E1: Estudado? | F1: Observações
A2: Língua Portuguesa | B2: Interpretação e compreensão textual | C2: Alta | D2: 🔥 | E2: Sim | F2: Simulado / Revisão em Lote
A3: Língua Portuguesa | B3: Reescrita de frases e parágrafos | C3: Alta | D3: 🔥 | E3: Sim | F3: Simulado / Revisão em Lote
A4: Língua Portuguesa | B4: Coesão textual (referenciação, conectores) | C4: Alta | D4: 🔥 | E4: Sim | F4: Simulado / Revisão em Lote
A5: Língua Portuguesa | B5: Morfossintaxe: classes de palavras | C5: Alta | D5: 🔥 | E5: Sim | F5: Simulado / Revisão em Lote
A6: Língua Portuguesa | B6: Concordância verbal e nominal | C6: Alta | D6: 🔥 | E6: Não
A7: Língua Portuguesa | B7: Regência verbal/nominal, crase e pontuação | C7: Alta | D7: 🔥 | E7: Não
A8: Legislação Institucional | B8: Estatuto 6.513/95: Hierarquia, disciplina, postos e graduações | C8: Alta | D8: 🔥 | E8: Sim | F8: Simulado / Revisão em Lote
A9: Legislação Institucional | B9: Estatuto 6.513/95: Direitos, deveres e ética policial-militar | C9: Alta | D9: 🔥 | E9: Sim | F9: Simulado / Revisão em Lote
A10: Legislação Institucional | B10: Estatuto 6.513/95: Ingresso, carreira e situações do PM | C10: Alta | D10: 🔥 | E10: Sim | F10: Simulado / Revisão em Lote
A11: Legislação Institucional | B11: Estatuto 6.513/95: Promoções (Art. 78 e 79-A) | C11: Alta | D11: - | E11: Sim | F11: Simulado / Revisão em Lote
A12: Legislação Institucional | B12: Lei 14.751/23: Disposições gerais e competências das PMs | C12: Alta | D12: - | E12: Sim | F12: Simulado / Revisão em Lote
A13: Legislação Institucional | B13: Lei 14.751/23: Organização (direção/apoio/execução/correição) | C13: Alta | D13: - | E13: Sim | F13: Simulado / Revisão em Lote
A14: Legislação Institucional | B14: Lei 14.751/23: Hierarquia, quadros e efetivos | C14: Alta | D14: - | E14: Não
A15: Legislação Institucional | B15: Lei 14.751/23: Garantias dos militares | C15: Média | D15: - | E15: Não
A16: Legislação Institucional | B16: Lei 12.896/26: Natureza jurídica e competências da PMMA (Art. 1-4) | C16: Alta | D16: 🔥 | E16: Não
A17: Legislação Institucional | B17: Lei 12.896/26: Estrutura organizacional - 5 tipos de órgãos (Art. 5) | C17: Alta | D17: 🔥 | E17: Não
A18: Legislação Institucional | B18: Lei 12.896/26: Hierarquia militar e efetivo (Art. 89 e 92) | C18: Alta | D18: 🔥 | E18: Não
A19: Legislação Institucional | B19: Lei 12.896/26: Quadros de pessoal - QOEM, QOE, QP etc (Art. 93) | C19: Alta | D19: 🔥 | E19: Não
A20: Legislação Institucional | B20: Lei 12.896/26: Nomeação, designação e substituição (Art. 107-111) | C20: Média | D20: - | E20: Não
A21: História do Brasil | B21: Contribuição de índios e negros na formação do Brasil | C21: Média | D21: - | E21: Sim | F21: Simulado / Revisão em Lote
A22: História do Brasil | B22: Formação do Brasil Contemporâneo | C22: Média | D22: - | E22: Sim | F22: Simulado / Revisão em Lote
A23: História do Brasil | B23: República Velha e estruturas oligárquicas | C23: Alta | D23: 🔥 | E23: Sim | F23: Simulado / Revisão em Lote
A24: História do Brasil | B24: Economia e sociedade: o café | C24: Média | D24: - | E24: Não
A25: História do Brasil | B25: Revolução de 1930 | C25: Alta | D25: 🔥 | E25: Sim
A26: História do Brasil | B26: Era Vargas: política, economia e sociedade | C26: Alta | D26: 🔥 | E26: Não
A27: História do Brasil | B27: Período democrático (1945-1964) | C27: Média | D27: - | E27: Não
A28: História do Brasil | B28: Redemocratização e Constituição de 1946 | C28: Média | D28: - | E28: Não
A29: História do Brasil | B29: Industrialização do governo JK | C29: Média | D29: - | E29: Não
A30: História do Brasil | B30: Crise do regime democrático | C30: Média | D30: - | E30: Não
A31: História do Brasil | B31: Golpe de 1964 | C31: Alta | D31: 🔥 | E31: Não
A32: História do Brasil | B32: Crise do regime militar e redemocratização | C32: Alta | D32: 🔥 | E32: Não
A33: História do Brasil | B33: Brasil político: nação e território | C33: Baixa | D33: - | E33: Não
A34: História do Brasil | B34: Organização do Estado Brasileiro | C34: Baixa | D34: - | E34: Não
A35: História do Brasil | B35: As Constituições brasileiras | C35: Baixa | D35: - | E35: Não
A36: História do Maranhão | B36: França Equinocial: expedição de La Touche | C36: Alta | D36: 🔥 | E36: Sim | F36: Simulado / Revisão em Lote
A37: História do Maranhão | B37: Fundação de São Luís | C37: Alta | D37: 🔥 | E37: Sim | F37: Simulado / Revisão em Lote
A38: História do Maranhão | B38: Batalha de Guaxenduba | C38: Alta | D38: 🔥 | E38: Sim | F38: Simulado / Revisão em Lote
A39: História do Maranhão | B39: Capitães-mores do Maranhão | C39: Baixa | D39: - | E39: Sim
A40: História do Maranhão | B40: Invasão e expulsão dos holandeses | C40: Média | D40: - | E40: Não
...

Sheet Treinos
A1: Data | B1: Tipo de Treino | C1: Duração (min) | D1: Intensidade (1-5) | E1: Observações

Sheet TAF_Semanal
A1: Data | B1: Barra (repetições) | C1: Meio Sugado (reps/1min) | D1: Abdominal Remador (reps/1min) | E1: Corrida 12min (metros) | F1: Status Geral | G1: Observações
F2: =IF(AND(B2>=4,C2>=25,D2>=35,E2>=2200),"Apto","Abaixo")
F3: =IF(AND(B3>=4,C3>=25,D3>=35,E3>=2200),"Apto","Abaixo")
F4: =IF(AND(B4>=4,C4>=25,D4>=35,E4>=2200),"Apto","Abaixo")
F5: =IF(AND(B5>=4,C5>=25,D5>=35,E5>=2200),"Apto","Abaixo")
F6: =IF(AND(B6>=4,C6>=25,D6>=35,E6>=2200),"Apto","Abaixo")
F7: =IF(AND(B7>=4,C7>=25,D7>=35,E7>=2200),"Apto","Abaixo")
F8: =IF(AND(B8>=4,C8>=25,D8>=35,E8>=2200),"Apto","Abaixo")
F9: =IF(AND(B9>=4,C9>=25,D9>=35,E9>=2200),"Apto","Abaixo")
F10: =IF(AND(B10>=4,C10>=25,D10>=35,E10>=2200),"Apto","Abaixo")
F11: =IF(AND(B11>=4,C11>=25,D11>=35,E11>=2200),"Apto","Abaixo")
F12: =IF(AND(B12>=4,C12>=25,D12>=35,E12>=2200),"Apto","Abaixo")
F13: =IF(AND(B13>=4,C13>=25,D13>=35,E13>=2200),"Apto","Abaixo")
... F19: =IF(AND(B19>=4,C19>=25,D19>=35,E19>=2200),"Apto","Abaixo")
A21: Mínimos exigidos no edital (masculino):
A22: Barra: 4 reps | Meio Sugado: 25 reps | Abdominal: 35 reps | Corrida 12min: 2.200m

Sheet Simulado_Semanal
A1: Data | B1: Nº Simulado | C1: Qtd Questões P1 (Gerais) | D1: Acertos P1 | E1: Qtd Questões P2 (Específicos) | F1: Acertos P2 | G1: Nota Final (0-120) | H1: Tempo Gasto | I1: Observações
B2: 1 | G2: =IFERROR((D2-((C2-D2)))*1+((F2-(E2-F2))*1),"")
B3: 2 | G3: =IFERROR((D3-((C3-D3)))*1+((F3-(E3-F3))*1),"")
B4: 3 | G4: =IFERROR((D4-((C4-D4)))*1+((F4-(E4-F4))*1),"")
B5: 4 | G5: =IFERROR((D5-((C5-D5)))*1+((F5-(E5-F5))*1),"")
B6: 5 | G6: =IFERROR((D6-((C6-D6)))*1+((F6-(E6-F6))*1),"")
B7: 6 | G7: =IFERROR((D7-((C7-D7)))*1+((F7-(E7-F7))*1),"")
B8: 7 | G8: =IFERROR((D8-((C8-D8)))*1+((F8-(E8-F8))*1),"")
B9: 8 | G9: =IFERROR((D9-((C9-D9)))*1+((F9-(E9-F9))*1),"")
B10: 9 | G10: =IFERROR((D10-((C10-D10)))*1+((F10-(E10-F10))*1),"")
B11: 10 | G11: =IFERROR((D11-((C11-D11)))*1+((F11-(E11-F11))*1),"")
B12: 11 | G12: =IFERROR((D12-((C12-D12)))*1+((F12-(E12-F12))*1),"")
B13: 12 | G13: =IFERROR((D13-((C13-D13)))*1+((F13-(E13-F13))*1),"")
... B21: 20 | G21: =IFERROR((D21-((C21-D21)))*1+((F21-(E21-F21))*1),"")

Sheet Dados_Dashboard
A1: ⚙️ Aba auxiliar — não precisa mexer aqui. Alimenta os gráficos do Dashboard.
A3: Matéria | B3: Tópicos Estudados | C3: Total de Tópicos | D3: % Estudado | E3: Qtd Questões | F3: Acertos | G3: Taxa de Acerto
A4: Língua Portuguesa | B4: =COUNTIFS(Controle_Edital!$A$2:$A$93,A4,Controle_Edital!$E$2:$E$93,"Sim") | C4: =COUNTIF(Controle_Edital!$A$2:$A$93,A4) | D4: =IFERROR(B4/C4,0) | E4: =SUMIFS(Cronograma!$L$2:$L$156,Cronograma!$D$2:$D$156,A4) | F4: =SUMIFS(Cronograma!$M$2:$M$156,Cronograma!$D$2:$D$156,A4) | G4: =IFERROR(F4/E4,0)
A5: Legislação Institucional | B5: =COUNTIFS(Controle_Edital!$A$2:$A$93,A5,Controle_Edital!$E$2:$E$93,"Sim") | C5: =COUNTIF(Controle_Edital!$A$2:$A$93,A5) | D5: =IFERROR(B5/C5,0) | E5: =SUMIFS(Cronograma!$L$2:$L$156,Cronograma!$D$2:$D$156,A5) | F5: =SUMIFS(Cronograma!$M$2:$M$156,Cronograma!$D$2:$D$156,A5) | G5: =IFERROR(F5/E5,0)
A6: História do Brasil | B6: =COUNTIFS(Controle_Edital!$A$2:$A$93,A6,Controle_Edital!$E$2:$E$93,"Sim") | C6: =COUNTIF(Controle_Edital!$A$2:$A$93,A6) | D6: =IFERROR(B6/C6,0) | E6: =SUMIFS(Cronograma!$L$2:$L$156,Cronograma!$D$2:$D$156,A6) | F6: =SUMIFS(Cronograma!$M$2:$M$156,Cronograma!$D$2:$D$156,A6) | G6: =IFERROR(F6/E6,0)
A7: História do Maranhão | B7: =COUNTIFS(Controle_Edital!$A$2:$A$93,A7,Controle_Edital!$E$2:$E$93,"Sim") | C7: =COUNTIF(Controle_Edital!$A$2:$A$93,A7) | D7: =IFERROR(B7/C7,0) | E7: =SUMIFS(Cronograma!$L$2:$L$156,Cronograma!$D$2:$D$156,A7) | F7: =SUMIFS(Cronograma!$M$2:$M$156,Cronograma!$D$2:$D$156,A7) | G7: =IFERROR(F7/E7,0)
A8: Geografia do Brasil | B8: =COUNTIFS(Controle_Edital!$A$2:$A$93,A8,Controle_Edital!$E$2:$E$93,"Sim") | C8: =COUNTIF(Controle_Edital!$A$2:$A$93,A8) | D8: =IFERROR(B8/C8,0) | E8: =SUMIFS(Cronograma!$L$2:$L$156,Cronograma!$D$2:$D$156,A8) | F8: =SUMIFS(Cronograma!$M$2:$M$156,Cronograma!$D$2:$D$156,A8) | G8: =IFERROR(F8/E8,0)
A9: Geografia do Maranhão | B9: =COUNTIFS(Controle_Edital!$A$2:$A$93,A9,Controle_Edital!$E$2:$E$93,"Sim") | C9: =COUNTIF(Controle_Edital!$A$2:$A$93,A9) | D9: =IFERROR(B9/C9,0) | E9: =SUMIFS(Cronograma!$L$2:$L$156,Cronograma!$D$2:$D$156,A9) | F9: =SUMIFS(Cronograma!$M$2:$M$156,Cronograma!$D$2:$D$156,A9) | G9: =IFERROR(F9/E9,0)
A10: Raciocínio Lógico | B10: =COUNTIFS(Controle_Edital!$A$2:$A$93,A10,Controle_Edital!$E$2:$E$93,"Sim") | C10: =COUNTIF(Controle_Edital!$A$2:$A$93,A10) | D10: =IFERROR(B10/C10,0) | E10: =SUMIFS(Cronograma!$L$2:$L$156,Cronograma!$D$2:$D$156,A10) | F10: =SUMIFS(Cronograma!$M$2:$M$156,Cronograma!$D$2:$D$156,A10) | G10: =IFERROR(F10/E10,0)
A11: Noções de Informática | B11: =COUNTIFS(Controle_Edital!$A$2:$A$93,A11,Controle_Edital!$E$2:$E$93,"Sim") | C11: =COUNTIF(Controle_Edital!$A$2:$A$93,A11) | D11: =IFERROR(B11/C11,0) | E11: =SUMIFS(Cronograma!$L$2:$L$156,Cronograma!$D$2:$D$156,A11) | F11: =SUMIFS(Cronograma!$M$2:$M$156,Cronograma!$D$2:$D$156,A11) | G11: =IFERROR(F11/E11,0)
A14: Resumo Geral
A15: Estudado | B15: =COUNTIF(Controle_Edital!E2:E93,"Sim")
A16: Pendente | B16: =COUNTIF(Controle_Edital!E2:E93,"Não")

Sheet Registro_de_Estudos
A1: Data | B1: Matéria | C1: Assunto | D1: Tipo | E1: Tempo (min) | F1: Qtd Questões | G1: Acertos | H1: Erros | I1: Aproveitamento | J1: Anotações
A2: 11/08/2026 | B2: Legislação Institucional | C2: Estatuto 6.513/95: Hierarquia, disciplina, postos e graduações | D2: Teoria + Questões | E2: 0 | F2: 0 | G2: 0 | H2: 0 | I2: 0
A3: 11/08/2026 | B3: Legislação Institucional | C3: Estatuto 6.513/95: Direitos, deveres e ética policial-militar | D3: Teoria + Questões | E3: 0 | F3: 0 | G3: 0 | H3: 0 | I3: 0
A4: 11/08/2026 | B4: Legislação Institucional | C4: Estatuto 6.513/95: Ingresso, carreira e situações do PM | D4: Teoria + Questões | E4: 0 | F4: 0 | G4: 0 | H4: 0 | I4: 0
A5: 11/08/2026 | B5: História do Brasil | C5: Contribuição de índios e negros na formação do Brasil | D5: Teoria + Questões | E5: 0 | F5: 0 | G5: 0 | H5: 0 | I5: 0
A6: 11/08/2026 | B6: História do Brasil | C6: Formação do Brasil Contemporâneo | D6: Teoria + Questões | E6: 0 | F6: 0 | G6: 0 | H6: 0 | I6: 0
A7: 11/08/2026 | B7: História do Maranhão | C7: França Equinocial: expedição de La Touche | D7: Teoria + Questões | E7: 0 | F7: 0 | G7: 0 | H7: 0 | I7: 0
A8: 11/08/2026 | B8: Geografia do Brasil | C8: Integração à internacionalização da economia | D8: Teoria + Questões | E8: 0 | F8: 0 | G8: 0 | H8: 0 | I8: 0
A9: 11/08/2026 | B9: Geografia do Brasil | C9: Industrialização e organização do espaço | D9: Teoria + Questões | E9: 0 | F9: 0 | G9: 0 | H9: 0 | I9: 0
A10: 11/08/2026 | B10: Noções de Informática | C10: Sistema operacional: Windows e Linux | D10: Teoria + Questões | E10: 0 | F10: 0 | G10: 0 | H10: 0 | I10: 0
A11: 11/08/2026 | B11: História do Brasil | C11: República Velha e estruturas oligárquicas | D11: Teoria + Questões | E11: 0 | F11: 0 | G11: 0 | H11: 0 | I11: 0
A12: 11/08/2026 | B12: História do Maranhão | C12: Fundação de São Luís | D12: Teoria + Questões | E12: 0 | F12: 0 | G12: 0 | H12: 0 | I12: 0
A13: 11/08/2026 | B13: História do Maranhão | C13: Capitães-mores do Maranhão | D13: Teoria + Questões | E13: 0 | F13: 0 | G13: 0 | H13: 0 | I13: 0
... A19: 11/08/2026 | B19: História do Brasil | C19: Revolução de 1930 | D19: Teoria + Questões | E19: 0 | F19: 0 | G19: 0 | H19: 0 | I19: 0
A20: 11/08/2026 | B20: Língua Portuguesa | C20: Interpretação e compreensão textual | D20: Revisão | E20: 20 | F20: 4 | G20: 4 | H20: 0 | I20: 1 | J20: Simulado / Revisão em Lote
A21: 11/08/2026 | B21: Língua Portuguesa | C21: Reescrita de frases e parágrafos | D21: Revisão | E21: 20 | F21: 4 | G21: 3 | H21: 1 | I21: 0.75 | J21: Simulado / Revisão em Lote
A22: 11/08/2026 | B22: Legislação Institucional | C22: Estatuto 6.513/95: Hierarquia, disciplina, postos e graduações | D22: Revisão | E22: 20 | F22: 3 | G22: 3 | H22: 0 | I22: 1 | J22: Simulado / Revisão em Lote
A23: 11/08/2026 | B23: Legislação Institucional | C23: Estatuto 6.513/95: Direitos, deveres e ética policial-militar | D23: Revisão | E23: 20 | F23: 4 | G23: 4 | H23: 0 | I23: 1 | J23: Simulado / Revisão em Lote
A24: 11/08/2026 | B24: Legislação Institucional | C24: Estatuto 6.513/95: Ingresso, carreira e situações do PM | D24: Revisão | E24: 20 | F24: 4 | G24: 4 | H24: 0 | I24: 1 | J24: Simulado / Revisão em Lote
A25: 11/08/2026 | B25: História do Brasil | C25: Contribuição de índios e negros na formação do Brasil | D25: Revisão | E25: 20 | F25: 2 | G25: 2 | H25: 0 | I25: 1 | J25: Simulado / Revisão em Lote
A26: 11/08/2026 | B26: História do Brasil | C26: Formação do Brasil Contemporâneo | D26: Revisão | E26: 20 | F26: 2 | G26: 2 | H26: 0 | I26: 1 | J26: Simulado / Revisão em Lote
A27: 11/08/2026 | B27: História do Maranhão | C27: França Equinocial: expedição de La Touche | D27: Revisão | E27: 20 | F27: 3 | G27: 3 | H27: 0 | I27: 1 | J27: Simulado / Revisão em Lote
A28: 11/08/2026 | B28: Geografia do Brasil | C28: Integração à internacionalização da economia | D28: Revisão | E28: 20 | F28: 3 | G28: 3 | H28: 0 | I28: 1 | J28: Simulado / Revisão em Lote
A29: 11/08/2026 | B29: Geografia do Brasil | C29: Industrialização e organização do espaço | D29: Revisão | E29: 20 | F29: 2 | G29: 2 | H29: 0 | I29: 1 | J29: Simulado / Revisão em Lote
A30: 11/08/2026 | B30: Geografia do Maranhão | C30: Localização: superfície, limites e APAs | D30: Revisão | E30: 20 | F30: 4 | G30: 4 | H30: 0 | I30: 1 | J30: Simulado / Revisão em Lote
A31: 11/08/2026 | B31: Noções de Informática | C31: Sistema operacional: Windows e Linux | D31: Revisão | E31: 20 | F31: 5 | G31: 4 | H31: 1 | I31: 0.8 | J31: Simulado / Revisão em Lote
... A49: 11/08/2026 | B49: Simulado Geral | C49: Simulado completo (ver aba Simulado Semanal) | D49: Revisão | E49: 60 | F49: 0 | G49: 0 | H49: 0 | I49: 0 | J49: Simulado / Revisão em Lote

Sheet Caderno_de_Erros
A1: Data | B1: Matéria | C1: Assunto | D1: Enunciado/Questão | E1: Link do TecConcursos | F1: Minha Resposta | G1: Explicação/Gabarito
